2025-01-12 20:37:17,874 INFO    MainThread:23716 [wandb_setup.py:_flush():68] Current SDK version is 0.19.2
2025-01-12 20:37:17,874 INFO    MainThread:23716 [wandb_setup.py:_flush():68] Configure stats pid to 23716
2025-01-12 20:37:17,874 INFO    MainThread:23716 [wandb_setup.py:_flush():68] Loading settings from C:\Users\emilp\.config\wandb\settings
2025-01-12 20:37:17,874 INFO    MainThread:23716 [wandb_setup.py:_flush():68] Loading settings from C:\Users\emilp\Documents\GitHub\Y2B-2023-OT2_Twin\wandb\settings
2025-01-12 20:37:17,875 INFO    MainThread:23716 [wandb_setup.py:_flush():68] Loading settings from environment variables
2025-01-12 20:37:17,875 INFO    MainThread:23716 [wandb_init.py:_log_setup():523] Logging user logs to C:\Users\emilp\Documents\GitHub\Y2B-2023-OT2_Twin\wandb\run-20250112_203717-fspwwkwl\logs\debug.log
2025-01-12 20:37:17,889 INFO    MainThread:23716 [wandb_init.py:_log_setup():524] Logging internal logs to C:\Users\emilp\Documents\GitHub\Y2B-2023-OT2_Twin\wandb\run-20250112_203717-fspwwkwl\logs\debug-internal.log
2025-01-12 20:37:17,889 INFO    MainThread:23716 [wandb_init.py:init():641] calling init triggers
2025-01-12 20:37:17,889 INFO    MainThread:23716 [wandb_init.py:init():647] wandb.init called with sweep_config: {}
config: {}
2025-01-12 20:37:17,889 INFO    MainThread:23716 [wandb_init.py:init():674] starting backend
2025-01-12 20:37:18,310 INFO    MainThread:23716 [wandb_init.py:init():678] sending inform_init request
2025-01-12 20:37:18,354 INFO    MainThread:23716 [backend.py:_multiprocessing_setup():104] multiprocessing start_methods=spawn, using: spawn
2025-01-12 20:37:18,354 INFO    MainThread:23716 [wandb_init.py:init():693] backend started and connected
2025-01-12 20:37:18,355 INFO    MainThread:23716 [wandb_init.py:init():786] updated telemetry
2025-01-12 20:37:18,419 INFO    MainThread:23716 [wandb_init.py:init():818] communicating run to backend with 90.0 second timeout
2025-01-12 20:37:20,018 ERROR   MainThread:23716 [wandb_init.py:init():845] encountered error: failed to upsert bucket: returned error 401 Unauthorized: {"errors":[{"message":"user is not logged in","path":["upsertBucket"],"extensions":{"code":"PERMISSION_ERROR"}}],"data":{"upsertBucket":null}}
2025-01-12 20:37:20,018 ERROR   MainThread:23716 [wandb_init.py:init():1299] error in wandb.init()
Traceback (most recent call last):
  File "C:\Users\emilp\myenv\Lib\site-packages\wandb\sdk\wandb_init.py", line 1289, in init
    return wi.init()
           ^^^^^^^^^
  File "C:\Users\emilp\myenv\Lib\site-packages\wandb\sdk\wandb_init.py", line 851, in init
    raise error
wandb.errors.errors.CommError: failed to upsert bucket: returned error 401 Unauthorized: {"errors":[{"message":"user is not logged in","path":["upsertBucket"],"extensions":{"code":"PERMISSION_ERROR"}}],"data":{"upsertBucket":null}}
2025-01-12 20:37:20,038 WARNING MsgRouterThr:23716 [router.py:message_loop():75] message_loop has been closed
